[2024-01-21T22:16:45.562+0000] {taskinstance.py:1956} INFO - Dependencies all met for dep_context=non-requeueable deps ti=<TaskInstance: DAG-USER-DATA-TRANSFER.data_transfer_workflow manual__2024-01-21T22:16:35.366661+00:00 [queued]>
[2024-01-21T22:16:45.576+0000] {taskinstance.py:1956} INFO - Dependencies all met for dep_context=requeueable deps ti=<TaskInstance: DAG-USER-DATA-TRANSFER.data_transfer_workflow manual__2024-01-21T22:16:35.366661+00:00 [queued]>
[2024-01-21T22:16:45.576+0000] {taskinstance.py:2170} INFO - Starting attempt 1 of 2
[2024-01-21T22:16:45.646+0000] {taskinstance.py:2191} INFO - Executing <Task(PythonOperator): data_transfer_workflow> on 2024-01-21 22:16:35.366661+00:00
[2024-01-21T22:16:45.672+0000] {standard_task_runner.py:60} INFO - Started process 120 to run task
[2024-01-21T22:16:45.678+0000] {standard_task_runner.py:87} INFO - Running: ['airflow', 'tasks', 'run', 'DAG-USER-DATA-TRANSFER', 'data_transfer_workflow', 'manual__2024-01-21T22:16:35.366661+00:00', '--job-id', '30', '--raw', '--subdir', 'DAGS_FOLDER/airflowScheduler.py', '--cfg-path', '/tmp/tmpqcmka6g2']
[2024-01-21T22:16:45.680+0000] {standard_task_runner.py:88} INFO - Job 30: Subtask data_transfer_workflow
[2024-01-21T22:16:45.805+0000] {task_command.py:423} INFO - Running <TaskInstance: DAG-USER-DATA-TRANSFER.data_transfer_workflow manual__2024-01-21T22:16:35.366661+00:00 [running]> on host 268f37077841
[2024-01-21T22:16:46.229+0000] {taskinstance.py:2480} INFO - Exporting env vars: AIRFLOW_CTX_DAG_OWNER='Silviq' AIRFLOW_CTX_DAG_ID='DAG-USER-DATA-TRANSFER' AIRFLOW_CTX_TASK_ID='data_transfer_workflow' AIRFLOW_CTX_EXECUTION_DATE='2024-01-21T22:16:35.366661+00:00' AIRFLOW_CTX_TRY_NUMBER='1' AIRFLOW_CTX_DAG_RUN_ID='manual__2024-01-21T22:16:35.366661+00:00'
[2024-01-21T22:16:46.240+0000] {taskinstance.py:2698} ERROR - Task failed with exception
Traceback (most recent call last):
  File "/home/airflow/.local/lib/python3.8/site-packages/airflow/models/taskinstance.py", line 433, in _execute_task
    result = execute_callable(context=context, **execute_callable_kwargs)
  File "/home/airflow/.local/lib/python3.8/site-packages/airflow/operators/python.py", line 199, in execute
    return_value = self.execute_callable()
  File "/home/airflow/.local/lib/python3.8/site-packages/airflow/operators/python.py", line 216, in execute_callable
    return self.python_callable(*self.op_args, **self.op_kwargs)
  File "/opt/airflow/dags/app.py", line 8, in data_transfer_workflow
    df_list = get_dataframes()
  File "/opt/airflow/dags/readWithPands.py", line 7, in get_dataframes
    df_comments = pd.read_csv(f'{path}/{datasets[0]}.csv').fillna('')
  File "/home/airflow/.local/lib/python3.8/site-packages/pandas/io/parsers/readers.py", line 912, in read_csv
    return _read(filepath_or_buffer, kwds)
  File "/home/airflow/.local/lib/python3.8/site-packages/pandas/io/parsers/readers.py", line 577, in _read
    parser = TextFileReader(filepath_or_buffer, **kwds)
  File "/home/airflow/.local/lib/python3.8/site-packages/pandas/io/parsers/readers.py", line 1407, in __init__
    self._engine = self._make_engine(f, self.engine)
  File "/home/airflow/.local/lib/python3.8/site-packages/pandas/io/parsers/readers.py", line 1661, in _make_engine
    self.handles = get_handle(
  File "/home/airflow/.local/lib/python3.8/site-packages/pandas/io/common.py", line 859, in get_handle
    handle = open(
FileNotFoundError: [Errno 2] No such file or directory: 'C:/Users/MissLuckyBubble/Desktop/AI/python_direktoriq/csvs/comments.csv'
[2024-01-21T22:16:46.333+0000] {taskinstance.py:1138} INFO - Marking task as UP_FOR_RETRY. dag_id=DAG-USER-DATA-TRANSFER, task_id=data_transfer_workflow, execution_date=20240121T221635, start_date=20240121T221645, end_date=20240121T221646
[2024-01-21T22:16:46.376+0000] {standard_task_runner.py:107} ERROR - Failed to execute job 30 for task data_transfer_workflow ([Errno 2] No such file or directory: 'C:/Users/MissLuckyBubble/Desktop/AI/python_direktoriq/csvs/comments.csv'; 120)
[2024-01-21T22:16:46.415+0000] {local_task_job_runner.py:234} INFO - Task exited with return code 1
[2024-01-21T22:16:46.441+0000] {taskinstance.py:3280} INFO - 0 downstream tasks scheduled from follow-on schedule check
